Workbook

Sheet 📊 Dashboard
B2: 🏃 Zone 2 Training Tracker — Trirong
B3: เป้าหมาย: Zone 2 (140–154 bpm) ที่ Pace 7:00 /km ภายในธันวาคม 2026
B6: Zone 2 Target HR | D6: Resting HR ปัจจุบัน | F6: สัปดาห์นี้ (กม.) | H6: Zone 2 % เฉลี่ย
B7: 140–154 bpm | D7: =SETTINGS!C7 | F7: =IFERROR(SUMIF(LOG!D:D,WEEKNUM(TODAY(),2),LOG!G:G),0) | H7: =IFERROR(AVERAGEIF(LOG!D:D,WEEKNUM(TODAY(),2),LOG!L:L),0)
B10: 5 ครั้งล่าสุด
B11: วันที่ | C11: ประเภท | D11: เวลา (นาที) | E11: ระยะ (กม.) | F11: Pace avg | G11: HR เฉลี่ย | H11: HR Max | I11: Zone 2 % | J11: สถานะ
B12: {=IFERROR(INDEX(LOG!C:C,LARGE(IF(LOG!C:C<>"",ROW(LOG!C:C)),5)),"")} | C12: {=IFERROR(INDEX(LOG!E:E,LARGE(IF(LOG!C:C<>"",ROW(LOG!C:C)),5)),"")} | D12: {=IFERROR(INDEX(LOG!F:F,LARGE(IF(LOG!C:C<>"",ROW(LOG!C:C)),5)),"")} | E12: {=IFERROR(INDEX(LOG!G:G,LARGE(IF(LOG!C:C<>"",ROW(LOG!C:C)),5)),"")} | F12: {=IFERROR(INDEX(LOG!I:I,LARGE(IF(LOG!C:C<>"",ROW(LOG!C:C)),5)),"")} | G12: {=IFERROR(INDEX(LOG!J:J,LARGE(IF(LOG!C:C<>"",ROW(LOG!C:C)),5)),"")} | H12: {=IFERROR(INDEX(LOG!K:K,LARGE(IF(LOG!C:C<>"",ROW(LOG!C:C)),5)),"")} | I12: {=IFERROR(INDEX(LOG!L:L,LARGE(IF(LOG!C:C<>"",ROW(LOG!C:C)),5)),"")} | J12: {=IFERROR(IF(INDEX(LOG!J:J,LARGE(IF(LOG!C:C<>"",ROW(LOG!C:C)),5))>154,"🔴 เกิน Zone",IF(INDEX(LOG!J:J,LARGE(IF(LOG!C:C<>"",ROW(LOG!C:C)),5))<140,"🔵 ต่ำกว่า","✅ Zone 2"))," ")}
B13: {=IFERROR(INDEX(LOG!C:C,LARGE(IF(LOG!C:C<>"",ROW(LOG!C:C)),4)),"")} | C13: {=IFERROR(INDEX(LOG!E:E,LARGE(IF(LOG!C:C<>"",ROW(LOG!C:C)),4)),"")} | D13: {=IFERROR(INDEX(LOG!F:F,LARGE(IF(LOG!C:C<>"",ROW(LOG!C:C)),4)),"")} | E13: {=IFERROR(INDEX(LOG!G:G,LARGE(IF(LOG!C:C<>"",ROW(LOG!C:C)),4)),"")} | F13: {=IFERROR(INDEX(LOG!I:I,LARGE(IF(LOG!C:C<>"",ROW(LOG!C:C)),4)),"")} | G13: {=IFERROR(INDEX(LOG!J:J,LARGE(IF(LOG!C:C<>"",ROW(LOG!C:C)),4)),"")} | H13: {=IFERROR(INDEX(LOG!K:K,LARGE(IF(LOG!C:C<>"",ROW(LOG!C:C)),4)),"")} | I13: {=IFERROR(INDEX(LOG!L:L,LARGE(IF(LOG!C:C<>"",ROW(LOG!C:C)),4)),"")} | J13: {=IFERROR(IF(INDEX(LOG!J:J,LARGE(IF(LOG!C:C<>"",ROW(LOG!C:C)),4))>154,"🔴 เกิน Zone",IF(INDEX(LOG!J:J,LARGE(IF(LOG!C:C<>"",ROW(LOG!C:C)),4))<140,"🔵 ต่ำกว่า","✅ Zone 2"))," ")}
B14: {=IFERROR(INDEX(LOG!C:C,LARGE(IF(LOG!C:C<>"",ROW(LOG!C:C)),3)),"")} | C14: {=IFERROR(INDEX(LOG!E:E,LARGE(IF(LOG!C:C<>"",ROW(LOG!C:C)),3)),"")} | D14: {=IFERROR(INDEX(LOG!F:F,LARGE(IF(LOG!C:C<>"",ROW(LOG!C:C)),3)),"")} | E14: {=IFERROR(INDEX(LOG!G:G,LARGE(IF(LOG!C:C<>"",ROW(LOG!C:C)),3)),"")} | F14: {=IFERROR(INDEX(LOG!I:I,LARGE(IF(LOG!C:C<>"",ROW(LOG!C:C)),3)),"")} | G14: {=IFERROR(INDEX(LOG!J:J,LARGE(IF(LOG!C:C<>"",ROW(LOG!C:C)),3)),"")} | H14: {=IFERROR(INDEX(LOG!K:K,LARGE(IF(LOG!C:C<>"",ROW(LOG!C:C)),3)),"")} | I14: {=IFERROR(INDEX(LOG!L:L,LARGE(IF(LOG!C:C<>"",ROW(LOG!C:C)),3)),"")} | J14: {=IFERROR(IF(INDEX(LOG!J:J,LARGE(IF(LOG!C:C<>"",ROW(LOG!C:C)),3))>154,"🔴 เกิน Zone",IF(INDEX(LOG!J:J,LARGE(IF(LOG!C:C<>"",ROW(LOG!C:C)),3))<140,"🔵 ต่ำกว่า","✅ Zone 2"))," ")}
B15: {=IFERROR(INDEX(LOG!C:C,LARGE(IF(LOG!C:C<>"",ROW(LOG!C:C)),2)),"")} | C15: {=IFERROR(INDEX(LOG!E:E,LARGE(IF(LOG!C:C<>"",ROW(LOG!C:C)),2)),"")} | D15: {=IFERROR(INDEX(LOG!F:F,LARGE(IF(LOG!C:C<>"",ROW(LOG!C:C)),2)),"")} | E15: {=IFERROR(INDEX(LOG!G:G,LARGE(IF(LOG!C:C<>"",ROW(LOG!C:C)),2)),"")} | F15: {=IFERROR(INDEX(LOG!I:I,LARGE(IF(LOG!C:C<>"",ROW(LOG!C:C)),2)),"")} | G15: {=IFERROR(INDEX(LOG!J:J,LARGE(IF(LOG!C:C<>"",ROW(LOG!C:C)),2)),"")} | H15: {=IFERROR(INDEX(LOG!K:K,LARGE(IF(LOG!C:C<>"",ROW(LOG!C:C)),2)),"")} | I15: {=IFERROR(INDEX(LOG!L:L,LARGE(IF(LOG!C:C<>"",ROW(LOG!C:C)),2)),"")} | J15: {=IFERROR(IF(INDEX(LOG!J:J,LARGE(IF(LOG!C:C<>"",ROW(LOG!C:C)),2))>154,"🔴 เกิน Zone",IF(INDEX(LOG!J:J,LARGE(IF(LOG!C:C<>"",ROW(LOG!C:C)),2))<140,"🔵 ต่ำกว่า","✅ Zone 2"))," ")}
B16: {=IFERROR(INDEX(LOG!C:C,LARGE(IF(LOG!C:C<>"",ROW(LOG!C:C)),1)),"")} | C16: {=IFERROR(INDEX(LOG!E:E,LARGE(IF(LOG!C:C<>"",ROW(LOG!C:C)),1)),"")} | D16: {=IFERROR(INDEX(LOG!F:F,LARGE(IF(LOG!C:C<>"",ROW(LOG!C:C)),1)),"")} | E16: {=IFERROR(INDEX(LOG!G:G,LARGE(IF(LOG!C:C<>"",ROW(LOG!C:C)),1)),"")} | F16: {=IFERROR(INDEX(LOG!I:I,LARGE(IF(LOG!C:C<>"",ROW(LOG!C:C)),1)),"")} | G16: {=IFERROR(INDEX(LOG!J:J,LARGE(IF(LOG!C:C<>"",ROW(LOG!C:C)),1)),"")} | H16: {=IFERROR(INDEX(LOG!K:K,LARGE(IF(LOG!C:C<>"",ROW(LOG!C:C)),1)),"")} | I16: {=IFERROR(INDEX(LOG!L:L,LARGE(IF(LOG!C:C<>"",ROW(LOG!C:C)),1)),"")} | J16: {=IFERROR(IF(INDEX(LOG!J:J,LARGE(IF(LOG!C:C<>"",ROW(LOG!C:C)),1))>154,"🔴 เกิน Zone",IF(INDEX(LOG!J:J,LARGE(IF(LOG!C:C<>"",ROW(LOG!C:C)),1))<140,"🔵 ต่ำกว่า","✅ Zone 2"))," ")}
B18: 📈 สรุปรายเดือน
B19: เดือน | C19: จำนวนครั้ง | D19: ระยะรวม (กม.) | E19: เวลารวม (นาที) | F19: HR เฉลี่ย | G19: Zone 2 % เฉลี่ย | H19: Pace เฉลี่ย | I19: Long Run max (นาที) | J19: หมายเหตุ
B20: ก.พ. 2026 | C20: =COUNTIFS(LOG!H:H,2,LOG!C:C,"<>") | D20: =SUMIFS(LOG!G:G,LOG!H:H,2) | E20: =SUMIFS(LOG!F:F,LOG!H:H,2) | F20: =IFERROR(AVERAGEIFS(LOG!J:J,LOG!H:H,2),"-") | G20: =IFERROR(AVERAGEIFS(LOG!L:L,LOG!H:H,2),"-") | H20: =IFERROR(AVERAGEIFS(LOG!M:M,LOG!H:H,2),"-") | I20: =IFERROR(MAXIFS(LOG!F:F,LOG!H:H,2,LOG!E:E,"Long Run"),"-")
B21: มี.ค. 2026 | C21: =COUNTIFS(LOG!H:H,3,LOG!C:C,"<>") | D21: =SUMIFS(LOG!G:G,LOG!H:H,3) | E21: =SUMIFS(LOG!F:F,LOG!H:H,3) | F21: =IFERROR(AVERAGEIFS(LOG!J:J,LOG!H:H,3),"-") | G21: =IFERROR(AVERAGEIFS(LOG!L:L,LOG!H:H,3),"-") | H21: =IFERROR(AVERAGEIFS(LOG!M:M,LOG!H:H,3),"-") | I21: =IFERROR(MAXIFS(LOG!F:F,LOG!H:H,3,LOG!E:E,"Long Run"),"-")
B22: เม.ย. 2026 | C22: =COUNTIFS(LOG!H:H,4,LOG!C:C,"<>") | D22: =SUMIFS(LOG!G:G,LOG!H:H,4) | E22: =SUMIFS(LOG!F:F,LOG!H:H,4) | F22: =IFERROR(AVERAGEIFS(LOG!J:J,LOG!H:H,4),"-") | G22: =IFERROR(AVERAGEIFS(LOG!L:L,LOG!H:H,4),"-") | H22: =IFERROR(AVERAGEIFS(LOG!M:M,LOG!H:H,4),"-") | I22: =IFERROR(MAXIFS(LOG!F:F,LOG!H:H,4,LOG!E:E,"Long Run"),"-")
B23: พ.ค. 2026 | C23: =COUNTIFS(LOG!H:H,5,LOG!C:C,"<>") | D23: =SUMIFS(LOG!G:G,LOG!H:H,5) | E23: =SUMIFS(LOG!F:F,LOG!H:H,5) | F23: =IFERROR(AVERAGEIFS(LOG!J:J,LOG!H:H,5),"-") | G23: =IFERROR(AVERAGEIFS(LOG!L:L,LOG!H:H,5),"-") | H23: =IFERROR(AVERAGEIFS(LOG!M:M,LOG!H:H,5),"-") | I23: =IFERROR(MAXIFS(LOG!F:F,LOG!H:H,5,LOG!E:E,"Long Run"),"-")
B24: มิ.ย. 2026 | C24: =COUNTIFS(LOG!H:H,6,LOG!C:C,"<>") | D24: =SUMIFS(LOG!G:G,LOG!H:H,6) | E24: =SUMIFS(LOG!F:F,LOG!H:H,6) | F24: =IFERROR(AVERAGEIFS(LOG!J:J,LOG!H:H,6),"-") | G24: =IFERROR(AVERAGEIFS(LOG!L:L,LOG!H:H,6),"-") | H24: =IFERROR(AVERAGEIFS(LOG!M:M,LOG!H:H,6),"-") | I24: =IFERROR(MAXIFS(LOG!F:F,LOG!H:H,6,LOG!E:E,"Long Run"),"-")
B25: ก.ค. 2026 | C25: =COUNTIFS(LOG!H:H,7,LOG!C:C,"<>") | D25: =SUMIFS(LOG!G:G,LOG!H:H,7) | E25: =SUMIFS(LOG!F:F,LOG!H:H,7) | F25: =IFERROR(AVERAGEIFS(LOG!J:J,LOG!H:H,7),"-") | G25: =IFERROR(AVERAGEIFS(LOG!L:L,LOG!H:H,7),"-") | H25: =IFERROR(AVERAGEIFS(LOG!M:M,LOG!H:H,7),"-") | I25: =IFERROR(MAXIFS(LOG!F:F,LOG!H:H,7,LOG!E:E,"Long Run"),"-")
B26: ส.ค. 2026 | C26: =COUNTIFS(LOG!H:H,8,LOG!C:C,"<>") | D26: =SUMIFS(LOG!G:G,LOG!H:H,8) | E26: =SUMIFS(LOG!F:F,LOG!H:H,8) | F26: =IFERROR(AVERAGEIFS(LOG!J:J,LOG!H:H,8),"-") | G26: =IFERROR(AVERAGEIFS(LOG!L:L,LOG!H:H,8),"-") | H26: =IFERROR(AVERAGEIFS(LOG!M:M,LOG!H:H,8),"-") | I26: =IFERROR(MAXIFS(LOG!F:F,LOG!H:H,8,LOG!E:E,"Long Run"),"-")
B27: ก.ย. 2026 | C27: =COUNTIFS(LOG!H:H,9,LOG!C:C,"<>") | D27: =SUMIFS(LOG!G:G,LOG!H:H,9) | E27: =SUMIFS(LOG!F:F,LOG!H:H,9) | F27: =IFERROR(AVERAGEIFS(LOG!J:J,LOG!H:H,9),"-") | G27: =IFERROR(AVERAGEIFS(LOG!L:L,LOG!H:H,9),"-") | H27: =IFERROR(AVERAGEIFS(LOG!M:M,LOG!H:H,9),"-") | I27: =IFERROR(MAXIFS(LOG!F:F,LOG!H:H,9,LOG!E:E,"Long Run"),"-")
B28: ต.ค. 2026 | C28: =COUNTIFS(LOG!H:H,10,LOG!C:C,"<>") | D28: =SUMIFS(LOG!G:G,LOG!H:H,10) | E28: =SUMIFS(LOG!F:F,LOG!H:H,10) | F28: =IFERROR(AVERAGEIFS(LOG!J:J,LOG!H:H,10),"-") | G28: =IFERROR(AVERAGEIFS(LOG!L:L,LOG!H:H,10),"-") | H28: =IFERROR(AVERAGEIFS(LOG!M:M,LOG!H:H,10),"-") | I28: =IFERROR(MAXIFS(LOG!F:F,LOG!H:H,10,LOG!E:E,"Long Run"),"-")
B29: พ.ย. 2026 | C29: =COUNTIFS(LOG!H:H,11,LOG!C:C,"<>") | D29: =SUMIFS(LOG!G:G,LOG!H:H,11) | E29: =SUMIFS(LOG!F:F,LOG!H:H,11) | F29: =IFERROR(AVERAGEIFS(LOG!J:J,LOG!H:H,11),"-") | G29: =IFERROR(AVERAGEIFS(LOG!L:L,LOG!H:H,11),"-") | H29: =IFERROR(AVERAGEIFS(LOG!M:M,LOG!H:H,11),"-") | I29: =IFERROR(MAXIFS(LOG!F:F,LOG!H:H,11,LOG!E:E,"Long Run"),"-")
B30: ธ.ค. 2026 | C30: =COUNTIFS(LOG!H:H,12,LOG!C:C,"<>") | D30: =SUMIFS(LOG!G:G,LOG!H:H,12) | E30: =SUMIFS(LOG!F:F,LOG!H:H,12) | F30: =IFERROR(AVERAGEIFS(LOG!J:J,LOG!H:H,12),"-") | G30: =IFERROR(AVERAGEIFS(LOG!L:L,LOG!H:H,12),"-") | H30: =IFERROR(AVERAGEIFS(LOG!M:M,LOG!H:H,12),"-") | I30: =IFERROR(MAXIFS(LOG!F:F,LOG!H:H,12,LOG!E:E,"Long Run"),"-")
B32: 🎯 Progress to Goal: Pace 7:00 /km
B33: เดือน | C33: Zone 2 Pace (นาที/กม.) | D33: HR ที่ Pace 7:00 | E33: ห่างจากเป้า (วิ/กม.) | F33: Zone 2 %
B34: ก.พ. 2026 | C34: 11.5 | E34: =IFERROR((11.5-7)*60,"") | F34: 0.72
B35: มี.ค. 2026
B36: เม.ย. 2026
B37: พ.ค. 2026
B38: มิ.ย. 2026
B39: ก.ค. 2026
B40: ส.ค. 2026
B41: ก.ย. 2026
B42: ต.ค. 2026
B43: พ.ย. 2026
B44: ธ.ค. 2026

Sheet 🗓️ Annual Plan
B1: 🗓️ Zone 2 Training Plan 2026 — แผนเต็มปี
B2: เป้าหมาย: Zone 2 (140-154 bpm) ที่ Pace 7:00 /km · Trirong Bamrungketaudom · อายุ 27 · COROS Pace Pro
B4: Zone 2 HR Range | E4: Pace ตอนนี้ | G4: Pace เป้าหมาย | I4: ระยะเวลา | K4: Max HR / HRR
B5: =SETTINGS!C11&" - "&SETTINGS!C12&" bpm" | E5: ~11:30 /km (Zone 2) | G5: 7:00 /km | I5: มี.ค.-ธ.ค. 2026 | K5: ="Max HR: "&SETTINGS!C8&" | HRR: "&SETTINGS!C9
B8: 4 Phases Overview
B9: Phase | C9: Wk | D9: ช่วง | E9: เป้าหมายหลัก | F9: Easy Run | G9: Long Run | H9: Strides | I9: Tempo | J9: Zone 2 % | K9: Pace Z2 เป้า | L9: km/wk เป้า | M9: เพิ่ม km %/wk | N9: Milestone
B10: Phase 1 | C10: 1-6 | D10: มี.ค.-เม.ย. | E10: สร้าง Aerobic Base Zone 2 เคร่งครัด 100% | F10: 45-65 นาที 3x/สัปดาห์ | G10: 80-100 นาที 1x/สัปดาห์ | H10: 4x20วิ | I10: --- | J10: >=80% | K10: 11:00-12:30 | L10: 25-33 | M10: <=10% | N10: Long run 90+ นาที อยู่ใน Zone 2 ตลอด
B11: Phase 2 | C11: 7-14 | D11: พ.ค.-มิ.ย. | E11: เพิ่ม Volume สังเกต aerobic efficiency | F11: 55-75 นาที 3x/สัปดาห์ | G11: 100-110 นาที 1x/สัปดาห์ | H11: 6x20วิ | I11: --- | J11: >=82% | K11: 10:00-11:00 | L11: 30-38 | M11: <=10% | N11: Pace Zone 2 เร็วขึ้น ~30วิ/กม.
B12: Phase 3 | C12: 15-22 | D12: ก.ค.-ส.ค. | E12: Neuromuscular Speed Strides + Tempo | F12: 65-80 นาที 3x/สัปดาห์ | G12: 110-120 นาที 1x/สัปดาห์ | H12: 8x20วิ 2x/wk | I12: 20 นาที 1x/2wk | J12: >=83% | K12: 8:30-10:00 | L12: 35-43 | M12: <=10% | N12: Tempo pace 8:00-8:30
B13: Phase 4 | C13: 23-36 | D13: ก.ย.-ธ.ค. | E13: จบที่ Pace 7:00 Zone 2 Benchmark | F13: 70-80 นาที 3x/สัปดาห์ | G13: 120+ นาที 1x/สัปดาห์ | H13: 8x20วิ 2x/wk | I13: 25 นาที 1x/wk | J13: >=85% | K13: 7:00-9:00 | L13: 40-48 | M13: <=8% | N13: Zone 2 Pace 7:00 /km
B15: Milestones รายเดือน
B16: เดือน | C16: Phase | D16: เป้าหมาย | E16: KPI | F16: Pace Z2 เป้า | G16: HR เป้า | H16: Long Run (นาที) | I16: Zone 2 % เป้า | J16: km/wk เป้า | K16: Benchmark Test | L16: วิธีทดสอบ | M16: หมายเหตุ | N16: สัญญาณเตือน
B17: มี.ค. | C17: P1 | D17: สร้างนิสัย Zone 2 | E17: Long run 80+ นาที Zone 2 ตลอด | F17: 12:00 | G17: 140-154 | H17: 80 | I17: >=80% | J17: 25-30 | K17: --- | L17: บันทึก RHR ทุกวัน | M17: Long run HR > 154 ตลอด = ชะลอ | N17: Long run HR > 154 ตลอด = ชะลอ
B18: เม.ย. | C18: P1 | D18: Zone 2 สม่ำเสมอ | E18: Zone 2% >=80% ทุก session | F18: 11:30 | G18: 140-154 | H18: 90 | I18: >=80% | J18: 28-33 | K18: Cardiac Drift Test | L18: HR เพิ่มขึ้นเท่าไหร่ใน 60 นาที | M18: HR ไม่ลดลงใน Easy = พักไม่พอ | N18: HR ไม่ลดลงใน Easy = พักไม่พอ
B19: พ.ค. | C19: P2 | D19: เพิ่ม Volume | E19: Long run 100+ นาที Zone 2 | F19: 11:00 | G19: 140-154 | H19: 100 | I19: >=82% | J19: 30-36 | K19: --- | L19: เพิ่ม Cross-train 1x/wk | M19: Pace ไม่เร็วขึ้น = ทบทวน | N19: Pace ไม่เร็วขึ้น = ทบทวน
B20: มิ.ย. | C20: P2 | D20: Aerobic Efficiency | E20: Pace เร็วขึ้น ~30วิ จาก มี.ค. | F20: 10:30 | G20: 140-154 | H20: 110 | I20: >=82% | J20: 33-38 | K20: Benchmark 30 นาที | L20: วัด pace ที่ HR 147 bpm | M20: เปรียบกับ มี.ค. ต้องเร็วขึ้น | N20: เปรียบกับ มี.ค. ต้องเร็วขึ้น
B21: ก.ค. | C21: P3 | D21: Neuromuscular Speed | E21: Strides 8x20วิ 2x/สัปดาห์ | F21: 10:00 | G21: 140-154 | H21: 110 | I21: >=83% | J21: 35-40 | K21: --- | L21: เพิ่ม Strides ทุก wk | M21: Strides ต้องรู้สึกเบา ไม่เหนื่อย | N21: Strides ต้องรู้สึกเบา ไม่เหนื่อย
B22: ส.ค. | C22: P3 | D22: Tempo สั้น | E22: Tempo 20 นาที pace 8:00-8:30 | F22: 9:00 | G22: 140-154 | H22: 120 | I22: >=83% | J22: 38-43 | K22: HR ที่ pace 8:30 | L22: จด HR เฉลี่ย Tempo | M22: Tempo HR ควร < 165 bpm | N22: Tempo HR ควร < 165 bpm
B23: ก.ย. | C23: P4 | D23: Pace 9 Zone 2 | E23: 5กม. pace 9:00 HR < 154 | F23: 9:00 | G23: 140-154 | H23: 120 | I23: >=84% | J23: 40-45 | K23: Test 5กม. pace 9 | L23: วิ่ง 5กม. วัด HR avg | M23: HR > 154 = ยังต้องฝึกต่อ | N23: HR > 154 = ยังต้องฝึกต่อ
B24: ต.ค. | C24: P4 | D24: Pace 8 Zone 2 | E24: 5กม. pace 8:00 HR < 154 | F24: 8:00 | G24: 140-154 | H24: 120 | I24: >=84% | J24: 40-45 | K24: Test 5กม. pace 8 | L24: วิ่ง 5กม. วัด HR avg | M24: HR > 154 = รอ พ.ย. | N24: HR > 154 = รอ พ.ย.
B25: พ.ย. | C25: P4 | D25: Pace 7:30 Zone 2 | E25: 5กม. pace 7:30 HR < 154 | F25: 7:30 | G25: 140-154 | H25: 120 | I25: >=85% | J25: 42-48 | K25: Test 5กม. pace 7:30 | L25: วิ่ง 5กม. วัด HR avg | M25: HR < 154 = เข้าใกล้แล้ว | N25: HR < 154 = เข้าใกล้แล้ว
B26: ธ.ค. | C26: P4 | D26: GOAL COMPLETE | E26: Zone 2 pace 7:00 HR 140-154 | F26: 7:00 | G26: 140-154 | H26: 120 | I26: >=85% | J26: 42-48 | K26: FINAL TEST 5กม. | L26: วิ่ง 5กม. pace 7 วัด HR | M26: วัด HR avg ทั้ง 5กม. | N26: HR avg < 154 = สำเร็จ!
B28: ตัวชี้วัดที่ต้องติดตาม
B29: ตัวชี้วัด | C29: ความถี่ | D29: เป้าหมาย | E29: วิธีวัด | F29: สัญญาณ OK | G29: สัญญาณเตือน
B30: HR เฉลี่ย / session | C30: ทุกครั้ง | D30: < 154 bpm | E30: COROS หลัง run | F30: HR 140-154 | G30: HR > 158 = เกิน Zone 2
B31: Zone 2 % | C31: ทุกครั้ง | D31: >=80% | E31: LOG sheet | F31: >=80% | G31: < 70% = ต้องชะลอ
B32: Resting HR | C32: ทุกเช้า | D32: <=62 bpm | E32: วัดก่อนลุกจากเตียง | F32: คงที่/ลดลง | G32: เพิ่ม 5+ bpm = overtraining
B33: Cardiac Drift | C33: Long run | D33: < 10 bpm | E33: HR ปลาย - HR ต้น | F33: < 10 bpm | G33: Drift > 15 = aerobic ต่ำ
B34: Zone 2 Pace | C34: ทุกเดือน | D34: ดู milestone | E34: เปรียบ pace ที่ HR 147 | F34: เร็วขึ้นทุกเดือน | G34: ไม่เร็วขึ้น 2 เดือน = ทบทวน
B35: Weekly Distance | C35: ทุกสัปดาห์ | D35: ดูแผน | E35: WEEKLY sheet | F35: <=+10%/wk | G35: เพิ่ม > 10% = injury risk
B37: กฎสำคัญ Zone 2 Training
B38: Slow Down Rule
B39: ถ้า HR เกิน 154 bpm -> ชะลอเป็นเดินทันที รอ HR ลงมา 145 แล้วค่อยวิ่งต่อ Ego เป็นศัตรู Zone 2
B41: อากาศกรุงเทพฯ
B42: HR สูงขึ้น 5-10 bpm จากความร้อน = ปกติมาก วิ่งช่วง 05:00-06:30 หรือ 18:30-20:00
B44: 80/20 Rule
B45: 80% ของระยะทั้งหมด = Zone 2 (easy) | 20% = hard (strides, tempo) ถ้า hard > 20% = aerobic base พัฒนาช้า
B47: Recovery = Training
B48: นอน 7-9 ชม. = สำคัญเท่ากับวิ่ง | Resting HR สูงขึ้น 5+ bpm -> พักเพิ่ม 1 วัน
B50: 10% Rule
...

Sheet 📋 Weekly Plan
B1: Weekly Plan 36 Weeks - Zone 2 Training 2026
B2: คอลัมน์สีม่วง = Deload week | Long Run = session สำคัญที่สุด | กฎ: HR > 154 -> เดินทันที
B4: Easy Run | D4: Long Run | F4: Strides | H4: Tempo | J4: Deload Week | L4: ตัวเลขเป้า
B6: Phase 1 -- มี.ค.-เม.ย. -- Wk 1-6
B7: Wk | C7: วันที่ | D7: Phase | E7: สัปดาห์ | F7: จันทร์ Easy Run | G7: พุธ Easy Run | H7: พฤหัส Strides | I7: เสาร์ Long Run | J7: Z2% เป้า | K7: HR เป้า | L7: Pace Z2 เป้า | M7: km/wk เป้า | N7: โน้ต / Test
B8: Wk 1 | C8: 02 Mar | D8: Phase 1 | E8: Build | F8: Easy 45นาที 140-154 bpm | G8: Easy 45นาที 140-154 bpm | H8: 4x20วิ 30นาที Easy+Strides | I8: Long 80นาที Zone 2 STRICT | J8: >=80% | K8: 140-154 | L8: 11:00-12:30 | M8: 24-29
B9: Wk 2 | C9: 09 Mar | D9: Phase 1 | E9: Build | F9: Easy 48นาที 140-154 bpm | G9: Easy 48นาที 140-154 bpm | H9: 4x20วิ 30นาที Easy+Strides | I9: Long 83นาที Zone 2 STRICT | J9: >=80% | K9: 140-154 | L9: 11:00-12:30 | M9: 25-30
B10: Wk 3 | C10: 16 Mar | D10: Phase 1 | E10: Build | F10: Easy 51นาที 140-154 bpm | G10: Easy 51นาที 140-154 bpm | H10: 4x20วิ 30นาที Easy+Strides | I10: Long 86นาที Zone 2 STRICT | J10: >=80% | K10: 140-154 | L10: 11:00-12:30 | M10: 26-31
B11: Wk 4 | C11: 23 Mar | D11: Phase 1 | E11: Deload | F11: Easy 37นาที 140-154 bpm | G11: Easy 37นาที 140-154 bpm | H11: 4x20วิ (เบา) 30นาที Easy+Strides | I11: Long 53นาที Zone 2 STRICT | J11: >=80% | K11: 140-154 | L11: 11:00-12:30 | M11: 18-22 | N11: Deload -30%
B12: Wk 5 | C12: 30 Mar | D12: Phase 1 | E12: Build | F12: Easy 57นาที 140-154 bpm | G12: Easy 57นาที 140-154 bpm | H12: 4x20วิ 30นาที Easy+Strides | I12: Long 92นาที Zone 2 STRICT | J12: >=80% | K12: 140-154 | L12: 11:00-12:30 | M12: 28-33
B13: Wk 6 | C13: 06 Apr | D13: Phase 1 | E13: Build | F13: Easy 60นาที 140-154 bpm | G13: Easy 60นาที 140-154 bpm | H13: 4x20วิ 30นาที Easy+Strides | I13: Long 95นาที Zone 2 STRICT | J13: >=80% | K13: 140-154 | L13: 11:00-12:30 | M13: 29-34
B15: Phase 2 -- พ.ค.-มิ.ย. -- Wk 7-14
B16: Wk | C16: วันที่ | D16: Phase | E16: สัปดาห์ | F16: จันทร์ Easy Run | G16: พุธ Easy Run | H16: พฤหัส Strides | I16: เสาร์ Long Run | J16: Z2% เป้า | K16: HR เป้า | L16: Pace Z2 เป้า | M16: km/wk เป้า | N16: โน้ต / Test
B17: Wk 7 | C17: 13 Apr | D17: Phase 2 | E17: Build | F17: Easy 58นาที 140-154 bpm | G17: Easy 58นาที 140-154 bpm | H17: 6x20วิ 30นาที Easy+Strides | I17: Long 98นาที Zone 2 STRICT | J17: >=82% | K17: 140-154 | L17: 10:00-11:00 | M17: 29-35
B18: Wk 8 | C18: 20 Apr | D18: Phase 2 | E18: Deload | F18: Easy 42นาที 140-154 bpm | G18: Easy 42นาที 140-154 bpm | H18: 4x20วิ (เบา) 30นาที Easy+Strides | I18: Long 60นาที Zone 2 STRICT | J18: >=82% | K18: 140-154 | L18: 10:00-11:00 | M18: 21-25 | N18: Deload + Cardiac Drift Test
B19: Wk 9 | C19: 27 Apr | D19: Phase 2 | E19: Build | F19: Easy 62นาที 140-154 bpm | G19: Easy 62นาที 140-154 bpm | H19: 6x20วิ 30นาที Easy+Strides | I19: Long 104นาที Zone 2 STRICT | J19: >=82% | K19: 140-154 | L19: 10:00-11:00 | M19: 31-37
B20: Wk 10 | C20: 04 May | D20: Phase 2 | E20: Build | F20: Easy 64นาที 140-154 bpm | G20: Easy 64นาที 140-154 bpm | H20: 6x20วิ 30นาที Easy+Strides | I20: Long 107นาที Zone 2 STRICT | J20: >=82% | K20: 140-154 | L20: 10:00-11:00 | M20: 32-38
B21: Wk 11 | C21: 11 May | D21: Phase 2 | E21: Build | F21: Easy 66นาที 140-154 bpm | G21: Easy 66นาที 140-154 bpm | H21: 6x20วิ 30นาที Easy+Strides | I21: Long 110นาที Zone 2 STRICT | J21: >=82% | K21: 140-154 | L21: 10:00-11:00 | M21: 33-39
B22: Wk 12 | C22: 18 May | D22: Phase 2 | E22: Deload | F22: Easy 47นาที 140-154 bpm | G22: Easy 47นาที 140-154 bpm | H22: 4x20วิ (เบา) 30นาที Easy+Strides | I22: Long 67นาที Zone 2 STRICT | J22: >=82% | K22: 140-154 | L22: 10:00-11:00 | M22: 23-28 | N22: Deload + เปรียบ pace กับ wk1
B23: Wk 13 | C23: 25 May | D23: Phase 2 | E23: Build | F23: Easy 70นาที 140-154 bpm | G23: Easy 70นาที 140-154 bpm | H23: 6x20วิ 30นาที Easy+Strides | I23: Long 116นาที Zone 2 STRICT | J23: >=82% | K23: 140-154 | L23: 10:00-11:00 | M23: 35-41
B24: Wk 14 | C24: 01 Jun | D24: Phase 2 | E24: Build | F24: Easy 72นาที 140-154 bpm | G24: Easy 72นาที 140-154 bpm | H24: 6x20วิ 30นาที Easy+Strides | I24: Long 119นาที Zone 2 STRICT | J24: >=82% | K24: 140-154 | L24: 10:00-11:00 | M24: 36-42
B26: Phase 3 -- ก.ค.-ส.ค. -- Wk 15-22
B27: Wk | C27: วันที่ | D27: Phase | E27: สัปดาห์ | F27: จันทร์ Easy Run | G27: พุธ Easy Run | H27: พฤหัส Strides | I27: เสาร์ Long Run | J27: Z2% เป้า | K27: HR เป้า | L27: Pace Z2 เป้า | M27: km/wk เป้า | N27: โน้ต / Test
B28: Wk 15 | C28: 08 Jun | D28: Phase 3 | E28: Build | F28: Easy 68นาที 140-154 bpm | G28: Easy 68นาที 140-154 bpm | H28: 8x20วิ 30นาที Easy+Strides | I28: Long 122นาที Zone 2 STRICT | J28: >=83% | K28: 140-154 | L28: 9:00-10:00 | M28: 36-43
B29: Wk 16 | C29: 15 Jun | D29: Phase 3 | E29: Deload | F29: Easy 48นาที 140-154 bpm | G29: Easy 48นาที 140-154 bpm | H29: 4x20วิ (เบา) 30นาที Easy+Strides | I29: Long 75นาที Zone 2 STRICT | J29: >=83% | K29: 140-154 | L29: 9:00-10:00 | M29: 25-30 | N29: Deload + Benchmark pace 8:30
B30: Wk 17 | C30: 22 Jun | D30: Phase 3 | E30: Build | F30: Easy 70นาที 140-154 bpm | G30: Easy 70นาที 140-154 bpm | H30: 8x20วิ 30นาที Easy+Strides | I30: Long 128นาที Zone 2 STRICT | J30: >=83% | K30: 140-154 | L30: 9:00-10:00 | M30: 38-45
B31: Wk 18 | C31: 29 Jun | D31: Phase 3 | E31: Build | F31: Easy 71นาที 140-154 bpm | G31: Easy 71นาที 140-154 bpm | H31: 8x20วิ 30นาที Easy+Strides | I31: Long 131นาที Zone 2 STRICT | J31: >=83% | K31: 140-154 | L31: 9:00-10:00 | M31: 39-46 | N31: Tempo 20 นาที (พุธ)
B32: Wk 19 | C32: 06 Jul | D32: Phase 3 | E32: Build | F32: Easy 72นาที 140-154 bpm | G32: Easy 72นาที 140-154 bpm | H32: 8x20วิ 30นาที Easy+Strides | I32: Long 134นาที Zone 2 STRICT | J32: >=83% | K32: 140-154 | L32: 8:30-9:30 | M32: 40-47
B33: Wk 20 | C33: 13 Jul | D33: Phase 3 | E33: Deload | F33: Easy 51นาที 140-154 bpm | G33: Easy 51นาที 140-154 bpm | H33: 4x20วิ (เบา) 30นาที Easy+Strides | I33: Long 82นาที Zone 2 STRICT | J33: >=83% | K33: 140-154 | L33: 8:30-9:30 | M33: 28-33 | N33: Deload + Test 5km Zone 2
B34: Wk 21 | C34: 20 Jul | D34: Phase 3 | E34: Build | F34: Easy 74นาที 140-154 bpm | G34: Easy 74นาที 140-154 bpm | H34: 8x20วิ 30นาที Easy+Strides | I34: Long 140นาที Zone 2 STRICT | J34: >=83% | K34: 140-154 | L34: 8:30-9:30 | M34: 42-49
B35: Wk 22 | C35: 27 Jul | D35: Phase 3 | E35: Build | F35: Easy 75นาที 140-154 bpm | G35: Easy 75นาที 140-154 bpm | H35: 8x20วิ 30นาที Easy+Strides | I35: Long 140นาที Zone 2 STRICT | J35: >=83% | K35: 140-154 | L35: 8:30-9:30 | M35: 43-50 | N35: Tempo 20 นาที (พุธ)
B37: Phase 4 -- ก.ย.-ธ.ค. -- Wk 23-36
B38: Wk | C38: วันที่ | D38: Phase | E38: สัปดาห์ | F38: จันทร์ Easy Run | G38: พุธ Easy Run | H38: พฤหัส Strides | I38: เสาร์ Long Run | J38: Z2% เป้า | K38: HR เป้า | L38: Pace Z2 เป้า | M38: km/wk เป้า | N38: โน้ต / Test
B39: Wk 23 | C39: 03 Aug | D39: Phase 4 | E39: Build | F39: Easy 72นาที 140-154 bpm | G39: Easy 72นาที 140-154 bpm | H39: 8x20วิ 30นาที Easy+Strides | I39: Long 140นาที Zone 2 STRICT | J39: >=85% | K39: 140-154 | L39: 8:00-9:00 | M39: 39-47
B40: Wk 24 | C40: 10 Aug | D40: Phase 4 | E40: Deload | F40: Easy 51นาที 140-154 bpm | G40: Easy 51นาที 140-154 bpm | H40: 4x20วิ (เบา) 30นาที Easy+Strides | I40: Long 84นาที Zone 2 STRICT | J40: >=85% | K40: 140-154 | L40: 8:00-9:00 | M40: 27-32 | N40: Deload + Test 5km pace 9:00
B41: Wk 25 | C41: 17 Aug | D41: Phase 4 | E41: Build | F41: Easy 74นาที 140-154 bpm | G41: Easy 74นาที 140-154 bpm | H41: 8x20วิ 30นาที Easy+Strides | I41: Long 140นาที Zone 2 STRICT | J41: >=85% | K41: 140-154 | L41: 8:00-9:00 | M41: 40-48
B42: Wk 26 | C42: 24 Aug | D42: Phase 4 | E42: Build | F42: Easy 75นาที 140-154 bpm | G42: Easy 75นาที 140-154 bpm | H42: 8x20วิ 30นาที Easy+Strides | I42: Long 140นาที Zone 2 STRICT | J42: >=85% | K42: 140-154 | L42: 8:00-9:00 | M42: 40-48 | N42: Tempo 25 นาที (พุธ)
B43: Wk 27 | C43: 31 Aug | D43: Phase 4 | E43: Build | F43: Easy 76นาที 140-154 bpm | G43: Easy 76นาที 140-154 bpm | H43: 8x20วิ 30นาที Easy+Strides | I43: Long 140นาที Zone 2 STRICT | J43: >=85% | K43: 140-154 | L43: 7:30-8:30 | M43: 41-49
B44: Wk 28 | C44: 07 Sep | D44: Phase 4 | E44: Deload | F44: Easy 53นาที 140-154 bpm | G44: Easy 53นาที 140-154 bpm | H44: 4x20วิ (เบา) 30นาที Easy+Strides | I44: Long 84นาที Zone 2 STRICT | J44: >=85% | K44: 140-154 | L44: 7:30-8:30 | M44: 28-34 | N44: Deload + Test 5km pace 8:00
B45: Wk 29 | C45: 14 Sep | D45: Phase 4 | E45: Build | F45: Easy 78นาที 140-154 bpm | G45: Easy 78นาที 140-154 bpm | H45: 8x20วิ 30นาที Easy+Strides | I45: Long 140นาที Zone 2 STRICT | J45: >=85% | K45: 140-154 | L45: 7:30-8:30 | M45: 42-50
...

Sheet LOG
B2: 📝 Run Log — กรอกข้อมูลการวิ่งทุกครั้ง
B3: กรอก: วันที่ | ประเภท | เวลา | ระยะ | Pace avg | HR เฉลี่ย | HR Max | Zone 2 % | Pace ที่ Zone 2 ← คอลัมน์สีเขียวคำนวณอัตโนมัติ
B4: # | C4: วันที่ | D4: สัปดาห์ (auto) | E4: ประเภท | F4: เวลา (นาที) | G4: ระยะ (กม.) | H4: เดือน (auto) | I4: Pace avg (นาที/กม.) | J4: HR เฉลี่ย (bpm) | K4: HR Max (bpm) | L4: Zone 2 % (0–100) | M4: Pace ที่ Zone 2 (นาที/กม.) | N4: Cardiac Drift (bpm) | O4: อุณหภูมิ (°C) | P4: รองเท้า | Q4: โน้ต
B5: 1 | C5: 2026-02-14 | D5: =IFERROR(WEEKNUM(C5,2),"") | E5: Easy Run | F5: 50 | G5: 4.3 | H5: =IFERROR(MONTH(C5),"") | I5: 11.77 | J5: 147 | K5: 158 | L5: 0.85 | M5: 11.5 | N5: 3 | O5: 28 | P5: 👟
B6: 2 | C6: 2026-02-15 | D6: =IFERROR(WEEKNUM(C6,2),"") | E6: Long Run | F6: 100 | G6: 8.9 | H6: =IFERROR(MONTH(C6),"") | I6: 11.23 | J6: 158 | K6: 177 | L6: 0.28 | N6: 12 | O6: 28 | P6: 👟 ⚠ HR สูง
B7: 3 | C7: 2026-02-18 | D7: =IFERROR(WEEKNUM(C7,2),"") | E7: Easy Run | F7: 50 | G7: 4.1 | H7: =IFERROR(MONTH(C7),"") | I7: 12.23 | J7: 146 | K7: 156 | L7: 0.95 | M7: 12.2 | N7: 2 | O7: 30 | P7: 👟
B8: 4 | C8: 2026-02-21 | D8: =IFERROR(WEEKNUM(C8,2),"") | E8: Progressive | F8: 53 | G8: 4.5 | H8: =IFERROR(MONTH(C8),"") | I8: 11.82 | J8: 152 | K8: 170 | L8: 0.74 | M8: 11.8 | N8: 8 | O8: 29 | P8: 👟
B9: 5 | C9: 2026-02-22 | D9: =IFERROR(WEEKNUM(C9,2),"") | E9: Long Run | F9: 90 | G9: 7.1 | H9: =IFERROR(MONTH(C9),"") | I9: 12.72 | J9: 151 | K9: 170 | L9: 0.79 | M9: 12.7 | N9: 6 | O9: 31 | P9: 👟
B10: =IFERROR(ROW()-9,"") | D10: =IFERROR(WEEKNUM(C10,2),"") | H10: =IFERROR(MONTH(C10),"")
B11: =IFERROR(ROW()-9,"") | D11: =IFERROR(WEEKNUM(C11,2),"") | H11: =IFERROR(MONTH(C11),"")
B12: =IFERROR(ROW()-9,"") | D12: =IFERROR(WEEKNUM(C12,2),"") | H12: =IFERROR(MONTH(C12),"")
B13: =IFERROR(ROW()-9,"") | D13: =IFERROR(WEEKNUM(C13,2),"") | H13: =IFERROR(MONTH(C13),"")
B14: =IFERROR(ROW()-9,"") | D14: =IFERROR(WEEKNUM(C14,2),"") | H14: =IFERROR(MONTH(C14),"")
B15: =IFERROR(ROW()-9,"") | D15: =IFERROR(WEEKNUM(C15,2),"") | H15: =IFERROR(MONTH(C15),"")
B16: =IFERROR(ROW()-9,"") | D16: =IFERROR(WEEKNUM(C16,2),"") | H16: =IFERROR(MONTH(C16),"")
B17: =IFERROR(ROW()-9,"") | D17: =IFERROR(WEEKNUM(C17,2),"") | H17: =IFERROR(MONTH(C17),"")
B18: =IFERROR(ROW()-9,"") | D18: =IFERROR(WEEKNUM(C18,2),"") | H18: =IFERROR(MONTH(C18),"")
B19: =IFERROR(ROW()-9,"") | D19: =IFERROR(WEEKNUM(C19,2),"") | H19: =IFERROR(MONTH(C19),"")
B20: =IFERROR(ROW()-9,"") | D20: =IFERROR(WEEKNUM(C20,2),"") | H20: =IFERROR(MONTH(C20),"")
B21: =IFERROR(ROW()-9,"") | D21: =IFERROR(WEEKNUM(C21,2),"") | H21: =IFERROR(MONTH(C21),"")
... B59: =IFERROR(ROW()-9,"") | D59: =IFERROR(WEEKNUM(C59,2),"") | H59: =IFERROR(MONTH(C59),"")

Sheet WEEKLY
B2: 📅 Weekly Summary — สรุปรายสัปดาห์
B4: สัปดาห์ปัจจุบัน
B5: จำนวนครั้ง | C5: ระยะรวม (กม.) | D5: เวลารวม (นาที) | E5: HR เฉลี่ย | F5: Zone 2 % เฉลี่ย
B6: =COUNTIF(LOG!D:D,WEEKNUM(TODAY(),2)) | C6: =SUMIF(LOG!D:D,WEEKNUM(TODAY(),2),LOG!G:G) | D6: =SUMIF(LOG!D:D,WEEKNUM(TODAY(),2),LOG!F:F) | E6: =IFERROR(AVERAGEIF(LOG!D:D,WEEKNUM(TODAY(),2),LOG!J:J),"-") | F6: =IFERROR(AVERAGEIF(LOG!D:D,WEEKNUM(TODAY(),2),LOG!L:L),"-")
B8: ประวัติรายสัปดาห์
B9: สัปดาห์ที่ | C9: จำนวนครั้ง | D9: ระยะรวม | E9: เวลารวม | F9: HR avg | G9: Zone 2 % | H9: Long Run | I9: Pace Zone 2 | J9: เป้า (80%+ Z2)
B10: 1 | C10: =COUNTIFS(LOG!D:D,1) | D10: =SUMIFS(LOG!G:G,LOG!D:D,1) | E10: =SUMIFS(LOG!F:F,LOG!D:D,1) | F10: =IFERROR(AVERAGEIFS(LOG!J:J,LOG!D:D,1),"-") | G10: =IFERROR(AVERAGEIFS(LOG!L:L,LOG!D:D,1),"-") | H10: =IFERROR(MAXIFS(LOG!F:F,LOG!D:D,1,LOG!E:E,"Long Run"),"-") | I10: =IFERROR(AVERAGEIFS(LOG!M:M,LOG!D:D,1),"-") | J10: =IFERROR(IF(AVERAGEIFS(LOG!L:L,LOG!D:D,1)>=0.8,"✅ ผ่าน","❌ ยังไม่ผ่าน"),"-")
B11: 2 | C11: =COUNTIFS(LOG!D:D,2) | D11: =SUMIFS(LOG!G:G,LOG!D:D,2) | E11: =SUMIFS(LOG!F:F,LOG!D:D,2) | F11: =IFERROR(AVERAGEIFS(LOG!J:J,LOG!D:D,2),"-") | G11: =IFERROR(AVERAGEIFS(LOG!L:L,LOG!D:D,2),"-") | H11: =IFERROR(MAXIFS(LOG!F:F,LOG!D:D,2,LOG!E:E,"Long Run"),"-") | I11: =IFERROR(AVERAGEIFS(LOG!M:M,LOG!D:D,2),"-") | J11: =IFERROR(IF(AVERAGEIFS(LOG!L:L,LOG!D:D,2)>=0.8,"✅ ผ่าน","❌ ยังไม่ผ่าน"),"-")
B12: 3 | C12: =COUNTIFS(LOG!D:D,3) | D12: =SUMIFS(LOG!G:G,LOG!D:D,3) | E12: =SUMIFS(LOG!F:F,LOG!D:D,3) | F12: =IFERROR(AVERAGEIFS(LOG!J:J,LOG!D:D,3),"-") | G12: =IFERROR(AVERAGEIFS(LOG!L:L,LOG!D:D,3),"-") | H12: =IFERROR(MAXIFS(LOG!F:F,LOG!D:D,3,LOG!E:E,"Long Run"),"-") | I12: =IFERROR(AVERAGEIFS(LOG!M:M,LOG!D:D,3),"-") | J12: =IFERROR(IF(AVERAGEIFS(LOG!L:L,LOG!D:D,3)>=0.8,"✅ ผ่าน","❌ ยังไม่ผ่าน"),"-")
B13: 4 | C13: =COUNTIFS(LOG!D:D,4) | D13: =SUMIFS(LOG!G:G,LOG!D:D,4) | E13: =SUMIFS(LOG!F:F,LOG!D:D,4) | F13: =IFERROR(AVERAGEIFS(LOG!J:J,LOG!D:D,4),"-") | G13: =IFERROR(AVERAGEIFS(LOG!L:L,LOG!D:D,4),"-") | H13: =IFERROR(MAXIFS(LOG!F:F,LOG!D:D,4,LOG!E:E,"Long Run"),"-") | I13: =IFERROR(AVERAGEIFS(LOG!M:M,LOG!D:D,4),"-") | J13: =IFERROR(IF(AVERAGEIFS(LOG!L:L,LOG!D:D,4)>=0.8,"✅ ผ่าน","❌ ยังไม่ผ่าน"),"-")
B14: 5 | C14: =COUNTIFS(LOG!D:D,5) | D14: =SUMIFS(LOG!G:G,LOG!D:D,5) | E14: =SUMIFS(LOG!F:F,LOG!D:D,5) | F14: =IFERROR(AVERAGEIFS(LOG!J:J,LOG!D:D,5),"-") | G14: =IFERROR(AVERAGEIFS(LOG!L:L,LOG!D:D,5),"-") | H14: =IFERROR(MAXIFS(LOG!F:F,LOG!D:D,5,LOG!E:E,"Long Run"),"-") | I14: =IFERROR(AVERAGEIFS(LOG!M:M,LOG!D:D,5),"-") | J14: =IFERROR(IF(AVERAGEIFS(LOG!L:L,LOG!D:D,5)>=0.8,"✅ ผ่าน","❌ ยังไม่ผ่าน"),"-")
B15: 6 | C15: =COUNTIFS(LOG!D:D,6) | D15: =SUMIFS(LOG!G:G,LOG!D:D,6) | E15: =SUMIFS(LOG!F:F,LOG!D:D,6) | F15: =IFERROR(AVERAGEIFS(LOG!J:J,LOG!D:D,6),"-") | G15: =IFERROR(AVERAGEIFS(LOG!L:L,LOG!D:D,6),"-") | H15: =IFERROR(MAXIFS(LOG!F:F,LOG!D:D,6,LOG!E:E,"Long Run"),"-") | I15: =IFERROR(AVERAGEIFS(LOG!M:M,LOG!D:D,6),"-") | J15: =IFERROR(IF(AVERAGEIFS(LOG!L:L,LOG!D:D,6)>=0.8,"✅ ผ่าน","❌ ยังไม่ผ่าน"),"-")
B16: 7 | C16: =COUNTIFS(LOG!D:D,7) | D16: =SUMIFS(LOG!G:G,LOG!D:D,7) | E16: =SUMIFS(LOG!F:F,LOG!D:D,7) | F16: =IFERROR(AVERAGEIFS(LOG!J:J,LOG!D:D,7),"-") | G16: =IFERROR(AVERAGEIFS(LOG!L:L,LOG!D:D,7),"-") | H16: =IFERROR(MAXIFS(LOG!F:F,LOG!D:D,7,LOG!E:E,"Long Run"),"-") | I16: =IFERROR(AVERAGEIFS(LOG!M:M,LOG!D:D,7),"-") | J16: =IFERROR(IF(AVERAGEIFS(LOG!L:L,LOG!D:D,7)>=0.8,"✅ ผ่าน","❌ ยังไม่ผ่าน"),"-")
B17: 8 | C17: =COUNTIFS(LOG!D:D,8) | D17: =SUMIFS(LOG!G:G,LOG!D:D,8) | E17: =SUMIFS(LOG!F:F,LOG!D:D,8) | F17: =IFERROR(AVERAGEIFS(LOG!J:J,LOG!D:D,8),"-") | G17: =IFERROR(AVERAGEIFS(LOG!L:L,LOG!D:D,8),"-") | H17: =IFERROR(MAXIFS(LOG!F:F,LOG!D:D,8,LOG!E:E,"Long Run"),"-") | I17: =IFERROR(AVERAGEIFS(LOG!M:M,LOG!D:D,8),"-") | J17: =IFERROR(IF(AVERAGEIFS(LOG!L:L,LOG!D:D,8)>=0.8,"✅ ผ่าน","❌ ยังไม่ผ่าน"),"-")
B18: 9 | C18: =COUNTIFS(LOG!D:D,9) | D18: =SUMIFS(LOG!G:G,LOG!D:D,9) | E18: =SUMIFS(LOG!F:F,LOG!D:D,9) | F18: =IFERROR(AVERAGEIFS(LOG!J:J,LOG!D:D,9),"-") | G18: =IFERROR(AVERAGEIFS(LOG!L:L,LOG!D:D,9),"-") | H18: =IFERROR(MAXIFS(LOG!F:F,LOG!D:D,9,LOG!E:E,"Long Run"),"-") | I18: =IFERROR(AVERAGEIFS(LOG!M:M,LOG!D:D,9),"-") | J18: =IFERROR(IF(AVERAGEIFS(LOG!L:L,LOG!D:D,9)>=0.8,"✅ ผ่าน","❌ ยังไม่ผ่าน"),"-")
B19: 10 | C19: =COUNTIFS(LOG!D:D,10) | D19: =SUMIFS(LOG!G:G,LOG!D:D,10) | E19: =SUMIFS(LOG!F:F,LOG!D:D,10) | F19: =IFERROR(AVERAGEIFS(LOG!J:J,LOG!D:D,10),"-") | G19: =IFERROR(AVERAGEIFS(LOG!L:L,LOG!D:D,10),"-") | H19: =IFERROR(MAXIFS(LOG!F:F,LOG!D:D,10,LOG!E:E,"Long Run"),"-") | I19: =IFERROR(AVERAGEIFS(LOG!M:M,LOG!D:D,10),"-") | J19: =IFERROR(IF(AVERAGEIFS(LOG!L:L,LOG!D:D,10)>=0.8,"✅ ผ่าน","❌ ยังไม่ผ่าน"),"-")
B20: 11 | C20: =COUNTIFS(LOG!D:D,11) | D20: =SUMIFS(LOG!G:G,LOG!D:D,11) | E20: =SUMIFS(LOG!F:F,LOG!D:D,11) | F20: =IFERROR(AVERAGEIFS(LOG!J:J,LOG!D:D,11),"-") | G20: =IFERROR(AVERAGEIFS(LOG!L:L,LOG!D:D,11),"-") | H20: =IFERROR(MAXIFS(LOG!F:F,LOG!D:D,11,LOG!E:E,"Long Run"),"-") | I20: =IFERROR(AVERAGEIFS(LOG!M:M,LOG!D:D,11),"-") | J20: =IFERROR(IF(AVERAGEIFS(LOG!L:L,LOG!D:D,11)>=0.8,"✅ ผ่าน","❌ ยังไม่ผ่าน"),"-")
B21: 12 | C21: =COUNTIFS(LOG!D:D,12) | D21: =SUMIFS(LOG!G:G,LOG!D:D,12) | E21: =SUMIFS(LOG!F:F,LOG!D:D,12) | F21: =IFERROR(AVERAGEIFS(LOG!J:J,LOG!D:D,12),"-") | G21: =IFERROR(AVERAGEIFS(LOG!L:L,LOG!D:D,12),"-") | H21: =IFERROR(MAXIFS(LOG!F:F,LOG!D:D,12,LOG!E:E,"Long Run"),"-") | I21: =IFERROR(AVERAGEIFS(LOG!M:M,LOG!D:D,12),"-") | J21: =IFERROR(IF(AVERAGEIFS(LOG!L:L,LOG!D:D,12)>=0.8,"✅ ผ่าน","❌ ยังไม่ผ่าน"),"-")
B22: 13 | C22: =COUNTIFS(LOG!D:D,13) | D22: =SUMIFS(LOG!G:G,LOG!D:D,13) | E22: =SUMIFS(LOG!F:F,LOG!D:D,13) | F22: =IFERROR(AVERAGEIFS(LOG!J:J,LOG!D:D,13),"-") | G22: =IFERROR(AVERAGEIFS(LOG!L:L,LOG!D:D,13),"-") | H22: =IFERROR(MAXIFS(LOG!F:F,LOG!D:D,13,LOG!E:E,"Long Run"),"-") | I22: =IFERROR(AVERAGEIFS(LOG!M:M,LOG!D:D,13),"-") | J22: =IFERROR(IF(AVERAGEIFS(LOG!L:L,LOG!D:D,13)>=0.8,"✅ ผ่าน","❌ ยังไม่ผ่าน"),"-")
B23: 14 | C23: =COUNTIFS(LOG!D:D,14) | D23: =SUMIFS(LOG!G:G,LOG!D:D,14) | E23: =SUMIFS(LOG!F:F,LOG!D:D,14) | F23: =IFERROR(AVERAGEIFS(LOG!J:J,LOG!D:D,14),"-") | G23: =IFERROR(AVERAGEIFS(LOG!L:L,LOG!D:D,14),"-") | H23: =IFERROR(MAXIFS(LOG!F:F,LOG!D:D,14,LOG!E:E,"Long Run"),"-") | I23: =IFERROR(AVERAGEIFS(LOG!M:M,LOG!D:D,14),"-") | J23: =IFERROR(IF(AVERAGEIFS(LOG!L:L,LOG!D:D,14)>=0.8,"✅ ผ่าน","❌ ยังไม่ผ่าน"),"-")
B24: 15 | C24: =COUNTIFS(LOG!D:D,15) | D24: =SUMIFS(LOG!G:G,LOG!D:D,15) | E24: =SUMIFS(LOG!F:F,LOG!D:D,15) | F24: =IFERROR(AVERAGEIFS(LOG!J:J,LOG!D:D,15),"-") | G24: =IFERROR(AVERAGEIFS(LOG!L:L,LOG!D:D,15),"-") | H24: =IFERROR(MAXIFS(LOG!F:F,LOG!D:D,15,LOG!E:E,"Long Run"),"-") | I24: =IFERROR(AVERAGEIFS(LOG!M:M,LOG!D:D,15),"-") | J24: =IFERROR(IF(AVERAGEIFS(LOG!L:L,LOG!D:D,15)>=0.8,"✅ ผ่าน","❌ ยังไม่ผ่าน"),"-")
B25: 16 | C25: =COUNTIFS(LOG!D:D,16) | D25: =SUMIFS(LOG!G:G,LOG!D:D,16) | E25: =SUMIFS(LOG!F:F,LOG!D:D,16) | F25: =IFERROR(AVERAGEIFS(LOG!J:J,LOG!D:D,16),"-") | G25: =IFERROR(AVERAGEIFS(LOG!L:L,LOG!D:D,16),"-") | H25: =IFERROR(MAXIFS(LOG!F:F,LOG!D:D,16,LOG!E:E,"Long Run"),"-") | I25: =IFERROR(AVERAGEIFS(LOG!M:M,LOG!D:D,16),"-") | J25: =IFERROR(IF(AVERAGEIFS(LOG!L:L,LOG!D:D,16)>=0.8,"✅ ผ่าน","❌ ยังไม่ผ่าน"),"-")
B26: 17 | C26: =COUNTIFS(LOG!D:D,17) | D26: =SUMIFS(LOG!G:G,LOG!D:D,17) | E26: =SUMIFS(LOG!F:F,LOG!D:D,17) | F26: =IFERROR(AVERAGEIFS(LOG!J:J,LOG!D:D,17),"-") | G26: =IFERROR(AVERAGEIFS(LOG!L:L,LOG!D:D,17),"-") | H26: =IFERROR(MAXIFS(LOG!F:F,LOG!D:D,17,LOG!E:E,"Long Run"),"-") | I26: =IFERROR(AVERAGEIFS(LOG!M:M,LOG!D:D,17),"-") | J26: =IFERROR(IF(AVERAGEIFS(LOG!L:L,LOG!D:D,17)>=0.8,"✅ ผ่าน","❌ ยังไม่ผ่าน"),"-")
B27: 18 | C27: =COUNTIFS(LOG!D:D,18) | D27: =SUMIFS(LOG!G:G,LOG!D:D,18) | E27: =SUMIFS(LOG!F:F,LOG!D:D,18) | F27: =IFERROR(AVERAGEIFS(LOG!J:J,LOG!D:D,18),"-") | G27: =IFERROR(AVERAGEIFS(LOG!L:L,LOG!D:D,18),"-") | H27: =IFERROR(MAXIFS(LOG!F:F,LOG!D:D,18,LOG!E:E,"Long Run"),"-") | I27: =IFERROR(AVERAGEIFS(LOG!M:M,LOG!D:D,18),"-") | J27: =IFERROR(IF(AVERAGEIFS(LOG!L:L,LOG!D:D,18)>=0.8,"✅ ผ่าน","❌ ยังไม่ผ่าน"),"-")
B28: 19 | C28: =COUNTIFS(LOG!D:D,19) | D28: =SUMIFS(LOG!G:G,LOG!D:D,19) | E28: =SUMIFS(LOG!F:F,LOG!D:D,19) | F28: =IFERROR(AVERAGEIFS(LOG!J:J,LOG!D:D,19),"-") | G28: =IFERROR(AVERAGEIFS(LOG!L:L,LOG!D:D,19),"-") | H28: =IFERROR(MAXIFS(LOG!F:F,LOG!D:D,19,LOG!E:E,"Long Run"),"-") | I28: =IFERROR(AVERAGEIFS(LOG!M:M,LOG!D:D,19),"-") | J28: =IFERROR(IF(AVERAGEIFS(LOG!L:L,LOG!D:D,19)>=0.8,"✅ ผ่าน","❌ ยังไม่ผ่าน"),"-")
B29: 20 | C29: =COUNTIFS(LOG!D:D,20) | D29: =SUMIFS(LOG!G:G,LOG!D:D,20) | E29: =SUMIFS(LOG!F:F,LOG!D:D,20) | F29: =IFERROR(AVERAGEIFS(LOG!J:J,LOG!D:D,20),"-") | G29: =IFERROR(AVERAGEIFS(LOG!L:L,LOG!D:D,20),"-") | H29: =IFERROR(MAXIFS(LOG!F:F,LOG!D:D,20,LOG!E:E,"Long Run"),"-") | I29: =IFERROR(AVERAGEIFS(LOG!M:M,LOG!D:D,20),"-") | J29: =IFERROR(IF(AVERAGEIFS(LOG!L:L,LOG!D:D,20)>=0.8,"✅ ผ่าน","❌ ยังไม่ผ่าน"),"-")
B30: 21 | C30: =COUNTIFS(LOG!D:D,21) | D30: =SUMIFS(LOG!G:G,LOG!D:D,21) | E30: =SUMIFS(LOG!F:F,LOG!D:D,21) | F30: =IFERROR(AVERAGEIFS(LOG!J:J,LOG!D:D,21),"-") | G30: =IFERROR(AVERAGEIFS(LOG!L:L,LOG!D:D,21),"-") | H30: =IFERROR(MAXIFS(LOG!F:F,LOG!D:D,21,LOG!E:E,"Long Run"),"-") | I30: =IFERROR(AVERAGEIFS(LOG!M:M,LOG!D:D,21),"-") | J30: =IFERROR(IF(AVERAGEIFS(LOG!L:L,LOG!D:D,21)>=0.8,"✅ ผ่าน","❌ ยังไม่ผ่าน"),"-")
B31: 22 | C31: =COUNTIFS(LOG!D:D,22) | D31: =SUMIFS(LOG!G:G,LOG!D:D,22) | E31: =SUMIFS(LOG!F:F,LOG!D:D,22) | F31: =IFERROR(AVERAGEIFS(LOG!J:J,LOG!D:D,22),"-") | G31: =IFERROR(AVERAGEIFS(LOG!L:L,LOG!D:D,22),"-") | H31: =IFERROR(MAXIFS(LOG!F:F,LOG!D:D,22,LOG!E:E,"Long Run"),"-") | I31: =IFERROR(AVERAGEIFS(LOG!M:M,LOG!D:D,22),"-") | J31: =IFERROR(IF(AVERAGEIFS(LOG!L:L,LOG!D:D,22)>=0.8,"✅ ผ่าน","❌ ยังไม่ผ่าน"),"-")
B32: 23 | C32: =COUNTIFS(LOG!D:D,23) | D32: =SUMIFS(LOG!G:G,LOG!D:D,23) | E32: =SUMIFS(LOG!F:F,LOG!D:D,23) | F32: =IFERROR(AVERAGEIFS(LOG!J:J,LOG!D:D,23),"-") | G32: =IFERROR(AVERAGEIFS(LOG!L:L,LOG!D:D,23),"-") | H32: =IFERROR(MAXIFS(LOG!F:F,LOG!D:D,23,LOG!E:E,"Long Run"),"-") | I32: =IFERROR(AVERAGEIFS(LOG!M:M,LOG!D:D,23),"-") | J32: =IFERROR(IF(AVERAGEIFS(LOG!L:L,LOG!D:D,23)>=0.8,"✅ ผ่าน","❌ ยังไม่ผ่าน"),"-")
B33: 24 | C33: =COUNTIFS(LOG!D:D,24) | D33: =SUMIFS(LOG!G:G,LOG!D:D,24) | E33: =SUMIFS(LOG!F:F,LOG!D:D,24) | F33: =IFERROR(AVERAGEIFS(LOG!J:J,LOG!D:D,24),"-") | G33: =IFERROR(AVERAGEIFS(LOG!L:L,LOG!D:D,24),"-") | H33: =IFERROR(MAXIFS(LOG!F:F,LOG!D:D,24,LOG!E:E,"Long Run"),"-") | I33: =IFERROR(AVERAGEIFS(LOG!M:M,LOG!D:D,24),"-") | J33: =IFERROR(IF(AVERAGEIFS(LOG!L:L,LOG!D:D,24)>=0.8,"✅ ผ่าน","❌ ยังไม่ผ่าน"),"-")
B34: 25 | C34: =COUNTIFS(LOG!D:D,25) | D34: =SUMIFS(LOG!G:G,LOG!D:D,25) | E34: =SUMIFS(LOG!F:F,LOG!D:D,25) | F34: =IFERROR(AVERAGEIFS(LOG!J:J,LOG!D:D,25),"-") | G34: =IFERROR(AVERAGEIFS(LOG!L:L,LOG!D:D,25),"-") | H34: =IFERROR(MAXIFS(LOG!F:F,LOG!D:D,25,LOG!E:E,"Long Run"),"-") | I34: =IFERROR(AVERAGEIFS(LOG!M:M,LOG!D:D,25),"-") | J34: =IFERROR(IF(AVERAGEIFS(LOG!L:L,LOG!D:D,25)>=0.8,"✅ ผ่าน","❌ ยังไม่ผ่าน"),"-")
B35: 26 | C35: =COUNTIFS(LOG!D:D,26) | D35: =SUMIFS(LOG!G:G,LOG!D:D,26) | E35: =SUMIFS(LOG!F:F,LOG!D:D,26) | F35: =IFERROR(AVERAGEIFS(LOG!J:J,LOG!D:D,26),"-") | G35: =IFERROR(AVERAGEIFS(LOG!L:L,LOG!D:D,26),"-") | H35: =IFERROR(MAXIFS(LOG!F:F,LOG!D:D,26,LOG!E:E,"Long Run"),"-") | I35: =IFERROR(AVERAGEIFS(LOG!M:M,LOG!D:D,26),"-") | J35: =IFERROR(IF(AVERAGEIFS(LOG!L:L,LOG!D:D,26)>=0.8,"✅ ผ่าน","❌ ยังไม่ผ่าน"),"-")
B36: 27 | C36: =COUNTIFS(LOG!D:D,27) | D36: =SUMIFS(LOG!G:G,LOG!D:D,27) | E36: =SUMIFS(LOG!F:F,LOG!D:D,27) | F36: =IFERROR(AVERAGEIFS(LOG!J:J,LOG!D:D,27),"-") | G36: =IFERROR(AVERAGEIFS(LOG!L:L,LOG!D:D,27),"-") | H36: =IFERROR(MAXIFS(LOG!F:F,LOG!D:D,27,LOG!E:E,"Long Run"),"-") | I36: =IFERROR(AVERAGEIFS(LOG!M:M,LOG!D:D,27),"-") | J36: =IFERROR(IF(AVERAGEIFS(LOG!L:L,LOG!D:D,27)>=0.8,"✅ ผ่าน","❌ ยังไม่ผ่าน"),"-")
B37: 28 | C37: =COUNTIFS(LOG!D:D,28) | D37: =SUMIFS(LOG!G:G,LOG!D:D,28) | E37: =SUMIFS(LOG!F:F,LOG!D:D,28) | F37: =IFERROR(AVERAGEIFS(LOG!J:J,LOG!D:D,28),"-") | G37: =IFERROR(AVERAGEIFS(LOG!L:L,LOG!D:D,28),"-") | H37: =IFERROR(MAXIFS(LOG!F:F,LOG!D:D,28,LOG!E:E,"Long Run"),"-") | I37: =IFERROR(AVERAGEIFS(LOG!M:M,LOG!D:D,28),"-") | J37: =IFERROR(IF(AVERAGEIFS(LOG!L:L,LOG!D:D,28)>=0.8,"✅ ผ่าน","❌ ยังไม่ผ่าน"),"-")
B38: 29 | C38: =COUNTIFS(LOG!D:D,29) | D38: =SUMIFS(LOG!G:G,LOG!D:D,29) | E38: =SUMIFS(LOG!F:F,LOG!D:D,29) | F38: =IFERROR(AVERAGEIFS(LOG!J:J,LOG!D:D,29),"-") | G38: =IFERROR(AVERAGEIFS(LOG!L:L,LOG!D:D,29),"-") | H38: =IFERROR(MAXIFS(LOG!F:F,LOG!D:D,29,LOG!E:E,"Long Run"),"-") | I38: =IFERROR(AVERAGEIFS(LOG!M:M,LOG!D:D,29),"-") | J38: =IFERROR(IF(AVERAGEIFS(LOG!L:L,LOG!D:D,29)>=0.8,"✅ ผ่าน","❌ ยังไม่ผ่าน"),"-")
B39: 30 | C39: =COUNTIFS(LOG!D:D,30) | D39: =SUMIFS(LOG!G:G,LOG!D:D,30) | E39: =SUMIFS(LOG!F:F,LOG!D:D,30) | F39: =IFERROR(AVERAGEIFS(LOG!J:J,LOG!D:D,30),"-") | G39: =IFERROR(AVERAGEIFS(LOG!L:L,LOG!D:D,30),"-") | H39: =IFERROR(MAXIFS(LOG!F:F,LOG!D:D,30,LOG!E:E,"Long Run"),"-") | I39: =IFERROR(AVERAGEIFS(LOG!M:M,LOG!D:D,30),"-") | J39: =IFERROR(IF(AVERAGEIFS(LOG!L:L,LOG!D:D,30)>=0.8,"✅ ผ่าน","❌ ยังไม่ผ่าน"),"-")
B40: 31 | C40: =COUNTIFS(LOG!D:D,31) | D40: =SUMIFS(LOG!G:G,LOG!D:D,31) | E40: =SUMIFS(LOG!F:F,LOG!D:D,31) | F40: =IFERROR(AVERAGEIFS(LOG!J:J,LOG!D:D,31),"-") | G40: =IFERROR(AVERAGEIFS(LOG!L:L,LOG!D:D,31),"-") | H40: =IFERROR(MAXIFS(LOG!F:F,LOG!D:D,31,LOG!E:E,"Long Run"),"-") | I40: =IFERROR(AVERAGEIFS(LOG!M:M,LOG!D:D,31),"-") | J40: =IFERROR(IF(AVERAGEIFS(LOG!L:L,LOG!D:D,31)>=0.8,"✅ ผ่าน","❌ ยังไม่ผ่าน"),"-")
B41: 32 | C41: =COUNTIFS(LOG!D:D,32) | D41: =SUMIFS(LOG!G:G,LOG!D:D,32) | E41: =SUMIFS(LOG!F:F,LOG!D:D,32) | F41: =IFERROR(AVERAGEIFS(LOG!J:J,LOG!D:D,32),"-") | G41: =IFERROR(AVERAGEIFS(LOG!L:L,LOG!D:D,32),"-") | H41: =IFERROR(MAXIFS(LOG!F:F,LOG!D:D,32,LOG!E:E,"Long Run"),"-") | I41: =IFERROR(AVERAGEIFS(LOG!M:M,LOG!D:D,32),"-") | J41: =IFERROR(IF(AVERAGEIFS(LOG!L:L,LOG!D:D,32)>=0.8,"✅ ผ่าน","❌ ยังไม่ผ่าน"),"-")
B42: 33 | C42: =COUNTIFS(LOG!D:D,33) | D42: =SUMIFS(LOG!G:G,LOG!D:D,33) | E42: =SUMIFS(LOG!F:F,LOG!D:D,33) | F42: =IFERROR(AVERAGEIFS(LOG!J:J,LOG!D:D,33),"-") | G42: =IFERROR(AVERAGEIFS(LOG!L:L,LOG!D:D,33),"-") | H42: =IFERROR(MAXIFS(LOG!F:F,LOG!D:D,33,LOG!E:E,"Long Run"),"-") | I42: =IFERROR(AVERAGEIFS(LOG!M:M,LOG!D:D,33),"-") | J42: =IFERROR(IF(AVERAGEIFS(LOG!L:L,LOG!D:D,33)>=0.8,"✅ ผ่าน","❌ ยังไม่ผ่าน"),"-")
B43: 34 | C43: =COUNTIFS(LOG!D:D,34) | D43: =SUMIFS(LOG!G:G,LOG!D:D,34) | E43: =SUMIFS(LOG!F:F,LOG!D:D,34) | F43: =IFERROR(AVERAGEIFS(LOG!J:J,LOG!D:D,34),"-") | G43: =IFERROR(AVERAGEIFS(LOG!L:L,LOG!D:D,34),"-") | H43: =IFERROR(MAXIFS(LOG!F:F,LOG!D:D,34,LOG!E:E,"Long Run"),"-") | I43: =IFERROR(AVERAGEIFS(LOG!M:M,LOG!D:D,34),"-") | J43: =IFERROR(IF(AVERAGEIFS(LOG!L:L,LOG!D:D,34)>=0.8,"✅ ผ่าน","❌ ยังไม่ผ่าน"),"-")
...

Sheet SETTINGS
B2: ⚙️ ตั้งค่าข้อมูลนักวิ่ง
B4: การตั้งค่า | C4: ค่า | D4: หมายเหตุ
B5: ชื่อ | C5: Jokedose | D5: ชื่อนักวิ่ง
B6: อายุ (ปี) | C6: 27 | D6: ใช้คำนวณ Max HR
B7: Resting HR (bpm) | C7: 62 | D7: วัดตอนเช้าก่อนลุกจากเตียง
B8: Max HR (bpm) | C8: =220-C6 | D8: คำนวณจากอายุ (220 - อายุ)
B9: HRR | C9: =C8-C7 | D9: Heart Rate Reserve = Max HR - Resting HR
B10: Zone 2 Low (bpm) | C10: =ROUND(C9*0.6+C7,0) | D10: 60% HRR + Resting HR
B11: Zone 2 High (bpm) | C11: =ROUND(C9*0.7+C7,0) | D11: 70% HRR + Resting HR
B12: น้ำหนัก (กก.) | C12: 71.5
B13: ไขมัน (%) | C13: 22.2 | D13: จากเครื่องชั่ง ณ ก.พ. 2026
B14: อุปกรณ์ | C14: COROS Pace Pro
B15: เป้าหมาย Zone 2 Pace | C15: 7:00 | D15: นาที/กม. ภายในธ.ค. 2026
B16: Pace Zone 2 ปัจจุบัน | C16: 11:30 | D16: นาที/กม. (ก.พ. 2026)
B17: เป้าหมาย Zone 2 % ต่อ session | C17: 80% | D17: ขั้นต่ำ
B18: Max เพิ่ม distance ต่อสัปดาห์ | C18: 10% | D18: กฎ 10% rule
B21: Zone HR ของคุณ (คำนวณอัตโนมัติ)
B22: Zone 1 (Active Recovery) | C22: < 130 bpm | D22: เดินเร็ว หรือ Warm-up
B23: Zone 2 (Aerobic Base) ⭐ | C23: =C10&" – "&C11&" bpm" | D23: เป้าหมาย — ง่าย คุยได้
B24: Zone 3 (Aerobic) | C24: 155–162 bpm | D24: ปานกลาง — threshold
B25: Zone 4 (Threshold) | C25: 163–172 bpm | D25: หนัก — Tempo run
B26: Zone 5 (VO2 Max) | C26: > 173 bpm | D26: หนักมาก — interval
